[Sun Feb 02 15:41:52.043663 2020] [wsgi:error] [pid 2341] [client 52.73.190.55:43506] [2020-02-02 15:41:52,041] ERROR in app: Exception on /api/v1/db/read [POST]
[Sun Feb 02 15:41:52.043709 2020] [wsgi:error] [pid 2341] [client 52.73.190.55:43506] Traceback (most recent call last):
[Sun Feb 02 15:41:52.043714 2020] [wsgi:error] [pid 2341] [client 52.73.190.55:43506]   File "/var/www/html/env/lib/python3.6/site-packages/flask/app.py", line 2446, in wsgi_app
[Sun Feb 02 15:41:52.043718 2020] [wsgi:error] [pid 2341] [client 52.73.190.55:43506]     response = self.full_dispatch_request()
[Sun Feb 02 15:41:52.043722 2020] [wsgi:error] [pid 2341] [client 52.73.190.55:43506]   File "/var/www/html/env/lib/python3.6/site-packages/flask/app.py", line 1951, in full_dispatch_request
[Sun Feb 02 15:41:52.043725 2020] [wsgi:error] [pid 2341] [client 52.73.190.55:43506]     rv = self.handle_user_exception(e)
[Sun Feb 02 15:41:52.043729 2020] [wsgi:error] [pid 2341] [client 52.73.190.55:43506]   File "/var/www/html/env/lib/python3.6/site-packages/flask/app.py", line 1820, in handle_user_exception
[Sun Feb 02 15:41:52.043732 2020] [wsgi:error] [pid 2341] [client 52.73.190.55:43506]     reraise(exc_type, exc_value, tb)
[Sun Feb 02 15:41:52.043736 2020] [wsgi:error] [pid 2341] [client 52.73.190.55:43506]   File "/var/www/html/env/lib/python3.6/site-packages/flask/_compat.py", line 39, in reraise
[Sun Feb 02 15:41:52.043739 2020] [wsgi:error] [pid 2341] [client 52.73.190.55:43506]     raise value
[Sun Feb 02 15:41:52.043743 2020] [wsgi:error] [pid 2341] [client 52.73.190.55:43506]   File "/var/www/html/env/lib/python3.6/site-packages/flask/app.py", line 1949, in full_dispatch_request
[Sun Feb 02 15:41:52.043747 2020] [wsgi:error] [pid 2341] [client 52.73.190.55:43506]     rv = self.dispatch_request()
[Sun Feb 02 15:41:52.043750 2020] [wsgi:error] [pid 2341] [client 52.73.190.55:43506]   File "/var/www/html/env/lib/python3.6/site-packages/flask/app.py", line 1935, in dispatch_request
[Sun Feb 02 15:41:52.043754 2020] [wsgi:error] [pid 2341] [client 52.73.190.55:43506]     return self.view_functions[rule.endpoint](**req.view_args)
[Sun Feb 02 15:41:52.043757 2020] [wsgi:error] [pid 2341] [client 52.73.190.55:43506]   File "/var/www/html/hello.py", line 268, in read_db
[Sun Feb 02 15:41:52.043761 2020] [wsgi:error] [pid 2341] [client 52.73.190.55:43506]     cur.execute(sql)
[Sun Feb 02 15:41:52.043764 2020] [wsgi:error] [pid 2341] [client 52.73.190.55:43506]   File "/var/www/html/env/lib/python3.6/site-packages/pymysql/cursors.py", line 170, in execute
[Sun Feb 02 15:41:52.043768 2020] [wsgi:error] [pid 2341] [client 52.73.190.55:43506]     result = self._query(query)
[Sun Feb 02 15:41:52.043771 2020] [wsgi:error] [pid 2341] [client 52.73.190.55:43506]   File "/var/www/html/env/lib/python3.6/site-packages/pymysql/cursors.py", line 328, in _query
[Sun Feb 02 15:41:52.043775 2020] [wsgi:error] [pid 2341] [client 52.73.190.55:43506]     conn.query(q)
[Sun Feb 02 15:41:52.043778 2020] [wsgi:error] [pid 2341] [client 52.73.190.55:43506]   File "/var/www/html/env/lib/python3.6/site-packages/pymysql/connections.py", line 517, in query
[Sun Feb 02 15:41:52.043782 2020] [wsgi:error] [pid 2341] [client 52.73.190.55:43506]     self._affected_rows = self._read_query_result(unbuffered=unbuffered)
[Sun Feb 02 15:41:52.043786 2020] [wsgi:error] [pid 2341] [client 52.73.190.55:43506]   File "/var/www/html/env/lib/python3.6/site-packages/pymysql/connections.py", line 732, in _read_query_result
[Sun Feb 02 15:41:52.043789 2020] [wsgi:error] [pid 2341] [client 52.73.190.55:43506]     result.read()
[Sun Feb 02 15:41:52.043793 2020] [wsgi:error] [pid 2341] [client 52.73.190.55:43506]   File "/var/www/html/env/lib/python3.6/site-packages/pymysql/connections.py", line 1075, in read
[Sun Feb 02 15:41:52.043796 2020] [wsgi:error] [pid 2341] [client 52.73.190.55:43506]     first_packet = self.connection._read_packet()
[Sun Feb 02 15:41:52.043800 2020] [wsgi:error] [pid 2341] [client 52.73.190.55:43506]   File "/var/www/html/env/lib/python3.6/site-packages/pymysql/connections.py", line 684, in _read_packet
[Sun Feb 02 15:41:52.043807 2020] [wsgi:error] [pid 2341] [client 52.73.190.55:43506]     packet.check_error()
[Sun Feb 02 15:41:52.043811 2020] [wsgi:error] [pid 2341] [client 52.73.190.55:43506]   File "/var/www/html/env/lib/python3.6/site-packages/pymysql/protocol.py", line 220, in check_error
[Sun Feb 02 15:41:52.043815 2020] [wsgi:error] [pid 2341] [client 52.73.190.55:43506]     err.raise_mysql_exception(self._data)
[Sun Feb 02 15:41:52.043818 2020] [wsgi:error] [pid 2341] [client 52.73.190.55:43506]   File "/var/www/html/env/lib/python3.6/site-packages/pymysql/err.py", line 109, in raise_mysql_exception
[Sun Feb 02 15:41:52.043822 2020] [wsgi:error] [pid 2341] [client 52.73.190.55:43506]     raise errorclass(errno, errval)
[Sun Feb 02 15:41:52.043826 2020] [wsgi:error] [pid 2341] [client 52.73.190.55:43506] pymysql.err.ProgrammingError: (1146, "Table 'Cloud.Rides' doesn't exist")
[Sun Feb 02 15:41:52.043850 2020] [wsgi:error] [pid 2341] [client 52.73.190.55:43506] 
[Sun Feb 02 15:41:52.046882 2020] [wsgi:error] [pid 2346] [client 49.206.10.45:50725] [2020-02-02 15:41:52,045] ERROR in app: Exception on /api/v1/rides [GET]
[Sun Feb 02 15:41:52.046906 2020] [wsgi:error] [pid 2346] [client 49.206.10.45:50725] Traceback (most recent call last):
[Sun Feb 02 15:41:52.046910 2020] [wsgi:error] [pid 2346] [client 49.206.10.45:50725]   File "/var/www/html/env/lib/python3.6/site-packages/flask/app.py", line 2446, in wsgi_app
[Sun Feb 02 15:41:52.046914 2020] [wsgi:error] [pid 2346] [client 49.206.10.45:50725]     response = self.full_dispatch_request()
[Sun Feb 02 15:41:52.046918 2020] [wsgi:error] [pid 2346] [client 49.206.10.45:50725]   File "/var/www/html/env/lib/python3.6/site-packages/flask/app.py", line 1951, in full_dispatch_request
[Sun Feb 02 15:41:52.046922 2020] [wsgi:error] [pid 2346] [client 49.206.10.45:50725]     rv = self.handle_user_exception(e)
[Sun Feb 02 15:41:52.046925 2020] [wsgi:error] [pid 2346] [client 49.206.10.45:50725]   File "/var/www/html/env/lib/python3.6/site-packages/flask/app.py", line 1820, in handle_user_exception
[Sun Feb 02 15:41:52.046929 2020] [wsgi:error] [pid 2346] [client 49.206.10.45:50725]     reraise(exc_type, exc_value, tb)
[Sun Feb 02 15:41:52.046932 2020] [wsgi:error] [pid 2346] [client 49.206.10.45:50725]   File "/var/www/html/env/lib/python3.6/site-packages/flask/_compat.py", line 39, in reraise
[Sun Feb 02 15:41:52.046936 2020] [wsgi:error] [pid 2346] [client 49.206.10.45:50725]     raise value
[Sun Feb 02 15:41:52.046939 2020] [wsgi:error] [pid 2346] [client 49.206.10.45:50725]   File "/var/www/html/env/lib/python3.6/site-packages/flask/app.py", line 1949, in full_dispatch_request
[Sun Feb 02 15:41:52.046943 2020] [wsgi:error] [pid 2346] [client 49.206.10.45:50725]     rv = self.dispatch_request()
[Sun Feb 02 15:41:52.046947 2020] [wsgi:error] [pid 2346] [client 49.206.10.45:50725]   File "/var/www/html/env/lib/python3.6/site-packages/flask/app.py", line 1935, in dispatch_request
[Sun Feb 02 15:41:52.046950 2020] [wsgi:error] [pid 2346] [client 49.206.10.45:50725]     return self.view_functions[rule.endpoint](**req.view_args)
[Sun Feb 02 15:41:52.046954 2020] [wsgi:error] [pid 2346] [client 49.206.10.45:50725]   File "/var/www/html/hello.py", line 124, in list_rides
[Sun Feb 02 15:41:52.046957 2020] [wsgi:error] [pid 2346] [client 49.206.10.45:50725]     res=eval(res)
[Sun Feb 02 15:41:52.046961 2020] [wsgi:error] [pid 2346] [client 49.206.10.45:50725]   File "<string>", line 1
[Sun Feb 02 15:41:52.046964 2020] [wsgi:error] [pid 2346] [client 49.206.10.45:50725]     <!DOCTYPE HTML PUBLIC "-//W3C//DTD HTML 3.2 Final//EN">
[Sun Feb 02 15:41:52.046968 2020] [wsgi:error] [pid 2346] [client 49.206.10.45:50725]     ^
[Sun Feb 02 15:41:52.046973 2020] [wsgi:error] [pid 2346] [client 49.206.10.45:50725] SyntaxError: invalid syntax
[Sun Feb 02 15:41:52.046995 2020] [wsgi:error] [pid 2346] [client 49.206.10.45:50725] 
[Sun Feb 02 15:42:17.443829 2020] [wsgi:error] [pid 2367] [client 52.73.190.55:43512] [2020-02-02 15:42:17,442] ERROR in app: Exception on /api/v1/db/read [POST]
[Sun Feb 02 15:42:17.443872 2020] [wsgi:error] [pid 2367] [client 52.73.190.55:43512] Traceback (most recent call last):
[Sun Feb 02 15:42:17.443877 2020] [wsgi:error] [pid 2367] [client 52.73.190.55:43512]   File "/var/www/html/env/lib/python3.6/site-packages/flask/app.py", line 2446, in wsgi_app
[Sun Feb 02 15:42:17.443880 2020] [wsgi:error] [pid 2367] [client 52.73.190.55:43512]     response = self.full_dispatch_request()
[Sun Feb 02 15:42:17.443884 2020] [wsgi:error] [pid 2367] [client 52.73.190.55:43512]   File "/var/www/html/env/lib/python3.6/site-packages/flask/app.py", line 1951, in full_dispatch_request
[Sun Feb 02 15:42:17.443888 2020] [wsgi:error] [pid 2367] [client 52.73.190.55:43512]     rv = self.handle_user_exception(e)
[Sun Feb 02 15:42:17.443891 2020] [wsgi:error] [pid 2367] [client 52.73.190.55:43512]   File "/var/www/html/env/lib/python3.6/site-packages/flask/app.py", line 1820, in handle_user_exception
[Sun Feb 02 15:42:17.443895 2020] [wsgi:error] [pid 2367] [client 52.73.190.55:43512]     reraise(exc_type, exc_value, tb)
[Sun Feb 02 15:42:17.443898 2020] [wsgi:error] [pid 2367] [client 52.73.190.55:43512]   File "/var/www/html/env/lib/python3.6/site-packages/flask/_compat.py", line 39, in reraise
[Sun Feb 02 15:42:17.443901 2020] [wsgi:error] [pid 2367] [client 52.73.190.55:43512]     raise value
[Sun Feb 02 15:42:17.443905 2020] [wsgi:error] [pid 2367] [client 52.73.190.55:43512]   File "/var/www/html/env/lib/python3.6/site-packages/flask/app.py", line 1949, in full_dispatch_request
[Sun Feb 02 15:42:17.443908 2020] [wsgi:error] [pid 2367] [client 52.73.190.55:43512]     rv = self.dispatch_request()
[Sun Feb 02 15:42:17.443912 2020] [wsgi:error] [pid 2367] [client 52.73.190.55:43512]   File "/var/www/html/env/lib/python3.6/site-packages/flask/app.py", line 1935, in dispatch_request
[Sun Feb 02 15:42:17.443915 2020] [wsgi:error] [pid 2367] [client 52.73.190.55:43512]     return self.view_functions[rule.endpoint](**req.view_args)
[Sun Feb 02 15:42:17.443919 2020] [wsgi:error] [pid 2367] [client 52.73.190.55:43512]   File "/var/www/html/hello.py", line 268, in read_db
[Sun Feb 02 15:42:17.443922 2020] [wsgi:error] [pid 2367] [client 52.73.190.55:43512]     cur.execute(sql)
[Sun Feb 02 15:42:17.443926 2020] [wsgi:error] [pid 2367] [client 52.73.190.55:43512]   File "/var/www/html/env/lib/python3.6/site-packages/pymysql/cursors.py", line 170, in execute
[Sun Feb 02 15:42:17.443941 2020] [wsgi:error] [pid 2367] [client 52.73.190.55:43512]     result = self._query(query)
[Sun Feb 02 15:42:17.443944 2020] [wsgi:error] [pid 2367] [client 52.73.190.55:43512]   File "/var/www/html/env/lib/python3.6/site-packages/pymysql/cursors.py", line 328, in _query
[Sun Feb 02 15:42:17.443948 2020] [wsgi:error] [pid 2367] [client 52.73.190.55:43512]     conn.query(q)
[Sun Feb 02 15:42:17.443951 2020] [wsgi:error] [pid 2367] [client 52.73.190.55:43512]   File "/var/www/html/env/lib/python3.6/site-packages/pymysql/connections.py", line 517, in query
[Sun Feb 02 15:42:17.443955 2020] [wsgi:error] [pid 2367] [client 52.73.190.55:43512]     self._affected_rows = self._read_query_result(unbuffered=unbuffered)
[Sun Feb 02 15:42:17.443959 2020] [wsgi:error] [pid 2367] [client 52.73.190.55:43512]   File "/var/www/html/env/lib/python3.6/site-packages/pymysql/connections.py", line 732, in _read_query_result
[Sun Feb 02 15:42:17.443962 2020] [wsgi:error] [pid 2367] [client 52.73.190.55:43512]     result.read()
[Sun Feb 02 15:42:17.443966 2020] [wsgi:error] [pid 2367] [client 52.73.190.55:43512]   File "/var/www/html/env/lib/python3.6/site-packages/pymysql/connections.py", line 1075, in read
[Sun Feb 02 15:42:17.443969 2020] [wsgi:error] [pid 2367] [client 52.73.190.55:43512]     first_packet = self.connection._read_packet()
[Sun Feb 02 15:42:17.443973 2020] [wsgi:error] [pid 2367] [client 52.73.190.55:43512]   File "/var/www/html/env/lib/python3.6/site-packages/pymysql/connections.py", line 684, in _read_packet
[Sun Feb 02 15:42:17.443976 2020] [wsgi:error] [pid 2367] [client 52.73.190.55:43512]     packet.check_error()
[Sun Feb 02 15:42:17.443983 2020] [wsgi:error] [pid 2367] [client 52.73.190.55:43512]   File "/var/www/html/env/lib/python3.6/site-packages/pymysql/protocol.py", line 220, in check_error
[Sun Feb 02 15:42:17.443986 2020] [wsgi:error] [pid 2367] [client 52.73.190.55:43512]     err.raise_mysql_exception(self._data)
[Sun Feb 02 15:42:17.443990 2020] [wsgi:error] [pid 2367] [client 52.73.190.55:43512]   File "/var/www/html/env/lib/python3.6/site-packages/pymysql/err.py", line 109, in raise_mysql_exception
[Sun Feb 02 15:42:17.443993 2020] [wsgi:error] [pid 2367] [client 52.73.190.55:43512]     raise errorclass(errno, errval)
[Sun Feb 02 15:42:17.443998 2020] [wsgi:error] [pid 2367] [client 52.73.190.55:43512] pymysql.err.ProgrammingError: (1146, "Table 'Cloud.Rides' doesn't exist")
[Sun Feb 02 15:42:17.444021 2020] [wsgi:error] [pid 2367] [client 52.73.190.55:43512] 
[Sun Feb 02 15:42:17.447021 2020] [wsgi:error] [pid 2344] [client 49.206.10.45:51190] [2020-02-02 15:42:17,445] ERROR in app: Exception on /api/v1/rides/101 [GET]
[Sun Feb 02 15:42:17.447044 2020] [wsgi:error] [pid 2344] [client 49.206.10.45:51190] Traceback (most recent call last):
[Sun Feb 02 15:42:17.447048 2020] [wsgi:error] [pid 2344] [client 49.206.10.45:51190]   File "/var/www/html/env/lib/python3.6/site-packages/flask/app.py", line 2446, in wsgi_app
[Sun Feb 02 15:42:17.447052 2020] [wsgi:error] [pid 2344] [client 49.206.10.45:51190]     response = self.full_dispatch_request()
[Sun Feb 02 15:42:17.447056 2020] [wsgi:error] [pid 2344] [client 49.206.10.45:51190]   File "/var/www/html/env/lib/python3.6/site-packages/flask/app.py", line 1951, in full_dispatch_request
[Sun Feb 02 15:42:17.447059 2020] [wsgi:error] [pid 2344] [client 49.206.10.45:51190]     rv = self.handle_user_exception(e)
[Sun Feb 02 15:42:17.447063 2020] [wsgi:error] [pid 2344] [client 49.206.10.45:51190]   File "/var/www/html/env/lib/python3.6/site-packages/flask/app.py", line 1820, in handle_user_exception
[Sun Feb 02 15:42:17.447067 2020] [wsgi:error] [pid 2344] [client 49.206.10.45:51190]     reraise(exc_type, exc_value, tb)
[Sun Feb 02 15:42:17.447070 2020] [wsgi:error] [pid 2344] [client 49.206.10.45:51190]   File "/var/www/html/env/lib/python3.6/site-packages/flask/_compat.py", line 39, in reraise
[Sun Feb 02 15:42:17.447085 2020] [wsgi:error] [pid 2344] [client 49.206.10.45:51190]     raise value
[Sun Feb 02 15:42:17.447089 2020] [wsgi:error] [pid 2344] [client 49.206.10.45:51190]   File "/var/www/html/env/lib/python3.6/site-packages/flask/app.py", line 1949, in full_dispatch_request
[Sun Feb 02 15:42:17.447104 2020] [wsgi:error] [pid 2344] [client 49.206.10.45:51190]     rv = self.dispatch_request()
[Sun Feb 02 15:42:17.447108 2020] [wsgi:error] [pid 2344] [client 49.206.10.45:51190]   File "/var/www/html/env/lib/python3.6/site-packages/flask/app.py", line 1935, in dispatch_request
[Sun Feb 02 15:42:17.447112 2020] [wsgi:error] [pid 2344] [client 49.206.10.45:51190]     return self.view_functions[rule.endpoint](**req.view_args)
[Sun Feb 02 15:42:17.447116 2020] [wsgi:error] [pid 2344] [client 49.206.10.45:51190]   File "/var/www/html/hello.py", line 151, in details_ride
[Sun Feb 02 15:42:17.447119 2020] [wsgi:error] [pid 2344] [client 49.206.10.45:51190]     res=eval(res)
[Sun Feb 02 15:42:17.447122 2020] [wsgi:error] [pid 2344] [client 49.206.10.45:51190]   File "<string>", line 1
[Sun Feb 02 15:42:17.447126 2020] [wsgi:error] [pid 2344] [client 49.206.10.45:51190]     <!DOCTYPE HTML PUBLIC "-//W3C//DTD HTML 3.2 Final//EN">
[Sun Feb 02 15:42:17.447129 2020] [wsgi:error] [pid 2344] [client 49.206.10.45:51190]     ^
[Sun Feb 02 15:42:17.447134 2020] [wsgi:error] [pid 2344] [client 49.206.10.45:51190] SyntaxError: invalid syntax
[Sun Feb 02 15:42:17.447155 2020] [wsgi:error] [pid 2344] [client 49.206.10.45:51190] 
[Sun Feb 02 15:49:48.796540 2020] [wsgi:error] [pid 2372] [client 49.206.10.45:51064] [2020-02-02 15:49:48,794] ERROR in app: Exception on /api/v1/db/read [POST]
[Sun Feb 02 15:49:48.796569 2020] [wsgi:error] [pid 2372] [client 49.206.10.45:51064] Traceback (most recent call last):
[Sun Feb 02 15:49:48.796583 2020] [wsgi:error] [pid 2372] [client 49.206.10.45:51064]   File "/var/www/html/env/lib/python3.6/site-packages/flask/app.py", line 2446, in wsgi_app
[Sun Feb 02 15:49:48.796587 2020] [wsgi:error] [pid 2372] [client 49.206.10.45:51064]     response = self.full_dispatch_request()
[Sun Feb 02 15:49:48.796591 2020] [wsgi:error] [pid 2372] [client 49.206.10.45:51064]   File "/var/www/html/env/lib/python3.6/site-packages/flask/app.py", line 1951, in full_dispatch_request
[Sun Feb 02 15:49:48.796594 2020] [wsgi:error] [pid 2372] [client 49.206.10.45:51064]     rv = self.handle_user_exception(e)
[Sun Feb 02 15:49:48.796598 2020] [wsgi:error] [pid 2372] [client 49.206.10.45:51064]   File "/var/www/html/env/lib/python3.6/site-packages/flask/app.py", line 1820, in handle_user_exception
[Sun Feb 02 15:49:48.796602 2020] [wsgi:error] [pid 2372] [client 49.206.10.45:51064]     reraise(exc_type, exc_value, tb)
[Sun Feb 02 15:49:48.796605 2020] [wsgi:error] [pid 2372] [client 49.206.10.45:51064]   File "/var/www/html/env/lib/python3.6/site-packages/flask/_compat.py", line 39, in reraise
[Sun Feb 02 15:49:48.796609 2020] [wsgi:error] [pid 2372] [client 49.206.10.45:51064]     raise value
[Sun Feb 02 15:49:48.796612 2020] [wsgi:error] [pid 2372] [client 49.206.10.45:51064]   File "/var/www/html/env/lib/python3.6/site-packages/flask/app.py", line 1949, in full_dispatch_request
[Sun Feb 02 15:49:48.796616 2020] [wsgi:error] [pid 2372] [client 49.206.10.45:51064]     rv = self.dispatch_request()
[Sun Feb 02 15:49:48.796619 2020] [wsgi:error] [pid 2372] [client 49.206.10.45:51064]   File "/var/www/html/env/lib/python3.6/site-packages/flask/app.py", line 1935, in dispatch_request
[Sun Feb 02 15:49:48.796623 2020] [wsgi:error] [pid 2372] [client 49.206.10.45:51064]     return self.view_functions[rule.endpoint](**req.view_args)
[Sun Feb 02 15:49:48.796627 2020] [wsgi:error] [pid 2372] [client 49.206.10.45:51064]   File "/var/www/html/hello.py", line 268, in read_db
[Sun Feb 02 15:49:48.796630 2020] [wsgi:error] [pid 2372] [client 49.206.10.45:51064]     cur.execute(sql)
[Sun Feb 02 15:49:48.796634 2020] [wsgi:error] [pid 2372] [client 49.206.10.45:51064]   File "/var/www/html/env/lib/python3.6/site-packages/pymysql/cursors.py", line 170, in execute
[Sun Feb 02 15:49:48.796637 2020] [wsgi:error] [pid 2372] [client 49.206.10.45:51064]     result = self._query(query)
[Sun Feb 02 15:49:48.796641 2020] [wsgi:error] [pid 2372] [client 49.206.10.45:51064]   File "/var/www/html/env/lib/python3.6/site-packages/pymysql/cursors.py", line 328, in _query
[Sun Feb 02 15:49:48.796644 2020] [wsgi:error] [pid 2372] [client 49.206.10.45:51064]     conn.query(q)
[Sun Feb 02 15:49:48.796648 2020] [wsgi:error] [pid 2372] [client 49.206.10.45:51064]   File "/var/www/html/env/lib/python3.6/site-packages/pymysql/connections.py", line 517, in query
[Sun Feb 02 15:49:48.796651 2020] [wsgi:error] [pid 2372] [client 49.206.10.45:51064]     self._affected_rows = self._read_query_result(unbuffered=unbuffered)
[Sun Feb 02 15:49:48.796655 2020] [wsgi:error] [pid 2372] [client 49.206.10.45:51064]   File "/var/www/html/env/lib/python3.6/site-packages/pymysql/connections.py", line 732, in _read_query_result
[Sun Feb 02 15:49:48.796658 2020] [wsgi:error] [pid 2372] [client 49.206.10.45:51064]     result.read()
[Sun Feb 02 15:49:48.796662 2020] [wsgi:error] [pid 2372] [client 49.206.10.45:51064]   File "/var/www/html/env/lib/python3.6/site-packages/pymysql/connections.py", line 1075, in read
[Sun Feb 02 15:49:48.796665 2020] [wsgi:error] [pid 2372] [client 49.206.10.45:51064]     first_packet = self.connection._read_packet()
[Sun Feb 02 15:49:48.796669 2020] [wsgi:error] [pid 2372] [client 49.206.10.45:51064]   File "/var/www/html/env/lib/python3.6/site-packages/pymysql/connections.py", line 684, in _read_packet
[Sun Feb 02 15:49:48.796673 2020] [wsgi:error] [pid 2372] [client 49.206.10.45:51064]     packet.check_error()
[Sun Feb 02 15:49:48.796676 2020] [wsgi:error] [pid 2372] [client 49.206.10.45:51064]   File "/var/www/html/env/lib/python3.6/site-packages/pymysql/protocol.py", line 220, in check_error
[Sun Feb 02 15:49:48.796683 2020] [wsgi:error] [pid 2372] [client 49.206.10.45:51064]     err.raise_mysql_exception(self._data)
[Sun Feb 02 15:49:48.796686 2020] [wsgi:error] [pid 2372] [client 49.206.10.45:51064]   File "/var/www/html/env/lib/python3.6/site-packages/pymysql/err.py", line 109, in raise_mysql_exception
[Sun Feb 02 15:49:48.796690 2020] [wsgi:error] [pid 2372] [client 49.206.10.45:51064]     raise errorclass(errno, errval)
[Sun Feb 02 15:49:48.796695 2020] [wsgi:error] [pid 2372] [client 49.206.10.45:51064] pymysql.err.InternalError: (1054, "Unknown column 'u' in 'field list'")
[Sun Feb 02 15:49:48.796722 2020] [wsgi:error] [pid 2372] [client 49.206.10.45:51064] 
